<?xml version="1.0"?>
<robot name="realsense2_camera" xmlns:xacro="http://ros.org/wiki/xacro">
    <xacro:arg name="use_nominal_extrinsics" default="false"/>
    <xacro:include filename="$(find realsense2_description)/urdf/_l515.urdf.xacro" />

    <link name="map" />

    <link name="base_link" />

    <joint name="map_to_base" type="continuous">
        <parent link="map"/>
        <child link="base_link"/>
    </joint>

    <link name="camera_frame" />
    <joint name="base_to_camera" type="fixed">
        <origin xyz="0 0 0" rpy="0 0 0"/>
        <parent link="base_link"/>
        <child link="camera_frame"/>
    </joint>


<!--    <link name="camera_frame">
            <visual>
            <origin xyz="0 0 0" rpy="0 0 0"/>
                <geometry>
                     <cylinder length="0.01" radius="0.2"/>
                </geometry>
            </visual>
    </link>

    <joint name="base_to_camera" type="fixed">
          <parent link="base_link"/>
          <child link="camera_frame"/>
    </joint>
-->
<!--
    <xacro:sensor_l515 parent="base_link" use_nominal_extrinsics="true">
        <origin xyz="0 0 0" rpy="0 0 0"/>
    </xacro:sensor_l515>
-->


</robot>
