<?xml version="1.0"?>
<robot name="realsense2_camera" xmlns:xacro="http://ros.org/wiki/xacro">
  <xacro:arg name="use_nominal_extrinsics" default="false"/>
  <xacro:arg name="name" default="camera"/>
  <xacro:include filename="$(find realsense2_description)/urdf/_l515.urdf.xacro" />

  <link name="map">
  </link>

  <link name="base_link" >
    <visual>
      <origin xyz="0 0 0" rpy="0 0 0"/>
      <geometry>
        <cylinder length="0.1" radius="0.2"/>
      </geometry>
    </visual>
  </link>

  <joint name="map_to_base" type="continuous"> <!--  -->
    <origin xyz="1 1 0" rpy="0 0 0"/>
    <parent link="map"/>
    <child link="base_link"/>
  </joint>


  <xacro:sensor_l515 parent="base_link" use_nominal_extrinsics="$(arg use_nominal_extrinsics)" name="$(arg name)">
    <origin xyz="0 0 0" rpy="0 0 0"/>
  </xacro:sensor_l515>

</robot>
